Workbook

Sheet README
A1: Item | B1: Value
A2: Issuer | B2: Fastned B.V.
A3: Data as of | B3: H1-2026
A4: Written | B4: 2026-10-24
A5: Units | B5: EUR m unless stated; days and headcount as counts; ratios as decimals
A6: Signs | B6: profits positive, losses negative; net interest = net finance cost, positive; capex and D&A positive
A7: Periods | B7: FY2025 = fiscal year ending in 2025; H1-2026 = half-year to 30 June 2026; FY2026E = a year after the last one reported: the company's budget or plan for it, or an amount falling due then. One column per year: debt falling due in a year since reported sits in that year (as the report before states it), a plan figure for such a year in its budget row; a band of years (FY2027E-FY2029E) stays in Facts
A8: Record | B8: one value per field and period: approved before pending, audited before unaudited, the later report wins where restated (mvp/screen.py)
A9: Status | B9: ok = approved by a named reviewer; rep = management representation, attested by a named officer; pend = extracted, pending review; rej = rejected; grey cell = pending, gold cell = management representation
A10: Sources | B10: every number links to its row in Facts; the row links to the page of the published PDF or to the web source
A11: Formulas | B11: Ratios are live Excel formulas on the Financials cells, the same formulas as the platform; one-off income = the items in Bridge
A12: Scope | B12: facts and arithmetic on printed formulas only: no rating, no score, no recommendation. Demo built from the company's public reports.

Sheet Financials
A1: EUR m unless stated | B1: FY2019 | C1: FY2020 | D1: FY2021 | E1: FY2022 | F1: FY2023 | G1: FY2024 | H1: FY2025 | I1: H1-2024 | J1: H1-2025 | K1: H1-2026 | L1: FY2026E | M1: FY2027E
A2: Identity
A3: Employees (FTE, period end) | E3: 146 | F3: 172 | G3: 265 | H3: 414 | J3: 354 | K3: 432
A4: Historical financials and quality of earnings
A5: Revenue | B5: 4.5 | C5: 6.3 | D5: 12.4 | E5: 36 | F5: 60.5 | G5: 83.8 | H5: 139.2 | I5: 37.8 | J5: 57.8 | K5: 83.5
A6: EBITDA (as reported) | D6: -12.6 | E6: -4.6 | F6: 4.6 | G6: 7.4 | H6: 14.8 | I6: 3.3 | J6: 3 | K6: 15.9
A7: EBITDA adjusted / underlying (as reported) | D7: -4.4 | E7: -4 | F7: 7.8 | G7: 8.7 | H7: 8.3 | I7: 3.2 | J7: 1.4 | K7: 13.7
A8: EBIT / operating result | E8: -14.4 | F8: -12.1 | G8: -16.1 | H8: -13.6 | J8: -10 | K8: -1.7
A9: Net result | D9: -24.6 | E9: -22.2 | F9: -19.3 | G9: -26.6 | H9: -30.2 | I9: -11.4 | J9: -18.3 | K9: -13
A10: Depreciation & amortisation | D10: 5.9 | E10: 10.3 | F10: 16.7 | G10: 23.4 | H10: 28.4 | I10: 9.8 | J10: 13 | K10: 17.6
A11: Net finance cost | D11: 6.2 | E11: 7.4 | F11: 6.8 | G11: 10.9 | H11: 16.4 | I11: 4.9 | J11: 8.2 | K11: 11.2
A12: Cash flow from operating activities | D12: -10 | E12: -10.8 | F12: -3.1 | G12: -7.6 | H12: -20.4 | J12: -6 | K12: -10.1
A13: Capex (PP&E + intangibles) | D13: 36.6 | E13: 67.5 | F13: 66.8 | G13: 68 | H13: 81.7 | J13: 41 | K13: 44.7
A14: Cash & equivalents | D14: 128.6 | E14: 149.5 | F14: 126.6 | G14: 117.4 | H14: 69.9 | J14: 112.7 | K14: 100.7
A15: Gross financial debt (bonds + loans, excl. leases) | E15: 112.9 | F15: 161 | G15: 226.5 | H15: 295.1 | K15: 379.5
A16: Lease liabilities | E16: 9.8 | F16: 21.2 | G16: 37.7 | H16: 62.9 | K16: 76.9
A17: Net debt (as reported) | G17: 146.8 | H17: 288
A18: Total equity | D18: 109.2 | E18: 160.6 | F18: 146.2 | G18: 122.7 | H18: 91.9 | J18: 104.1 | K18: 80.8
A19: Total assets | D19: 214.6 | E19: 315.2 | F19: 357.5 | G19: 426.7 | H19: 501.8 | K19: 595.3
A20: Days from year end to filing of the accounts | F20: 87 | G20: 85 | H20: 78 | K20: 37
A21: Income taxes paid (cash flow statement) | E21: 0 | F21: 0 | G21: 0 | H21: 0 | J21: 0 | K21: 0
A22: Transaction, plan, projections and downside
A23: Order book / contracted revenue (period end) | H23: 23.9
A24: Debt principal falling due in the period | F24: 8.9 | G24: 17 | H24: 21.9 | L24: 12.4 | M24: 7.3

Sheet Bridge
A1: Period | B1: One-off income inside EBITDA, as itemised in the reports | C1: EUR m counted | D1: Fact | E1: Rule

Sheet Ratios
A1: Live formulas on Financials | B1: FY2019 | C1: FY2020 | D1: FY2021 | E1: FY2022 | F1: FY2023 | G1: FY2024 | H1: FY2025 | I1: H1-2024 | J1: H1-2025 | K1: H1-2026 | L1: Formula
A2: One-off income inside EBITDA | B2: =SUMIF(Bridge!$A:$A,"FY2019",Bridge!$C:$C) | C2: =SUMIF(Bridge!$A:$A,"FY2020",Bridge!$C:$C) | D2: =SUMIF(Bridge!$A:$A,"FY2021",Bridge!$C:$C) | E2: =SUMIF(Bridge!$A:$A,"FY2022",Bridge!$C:$C) | F2: =SUMIF(Bridge!$A:$A,"FY2023",Bridge!$C:$C) | G2: =SUMIF(Bridge!$A:$A,"FY2024",Bridge!$C:$C) | H2: =SUMIF(Bridge!$A:$A,"FY2025",Bridge!$C:$C) | I2: =SUMIF(Bridge!$A:$A,"H1-2024",Bridge!$C:$C) | J2: =SUMIF(Bridge!$A:$A,"H1-2025",Bridge!$C:$C) | K2: =SUMIF(Bridge!$A:$A,"H1-2026",Bridge!$C:$C) | L2: SUM of Bridge for the period
A3: EBITDA excluding one-off income | D3: =(Financials!D6-SUMIF(Bridge!$A:$A,"FY2021",Bridge!$C:$C)) | E3: =(Financials!E6-SUMIF(Bridge!$A:$A,"FY2022",Bridge!$C:$C)) | F3: =(Financials!F6-SUMIF(Bridge!$A:$A,"FY2023",Bridge!$C:$C)) | G3: =(Financials!G6-SUMIF(Bridge!$A:$A,"FY2024",Bridge!$C:$C)) | H3: =(Financials!H6-SUMIF(Bridge!$A:$A,"FY2025",Bridge!$C:$C)) | I3: =(Financials!I6-SUMIF(Bridge!$A:$A,"H1-2024",Bridge!$C:$C)) | J3: =(Financials!J6-SUMIF(Bridge!$A:$A,"H1-2025",Bridge!$C:$C)) | K3: =(Financials!K6-SUMIF(Bridge!$A:$A,"H1-2026",Bridge!$C:$C)) | L3: EBITDA as reported − one-off income
A4: EBITDA margin excluding one-off income | D4: =IFERROR((Financials!D6-SUMIF(Bridge!$A:$A,"FY2021",Bridge!$C:$C))/Financials!D5,"") | E4: =IFERROR((Financials!E6-SUMIF(Bridge!$A:$A,"FY2022",Bridge!$C:$C))/Financials!E5,"") | F4: =IFERROR((Financials!F6-SUMIF(Bridge!$A:$A,"FY2023",Bridge!$C:$C))/Financials!F5,"") | G4: =IFERROR((Financials!G6-SUMIF(Bridge!$A:$A,"FY2024",Bridge!$C:$C))/Financials!G5,"") | H4: =IFERROR((Financials!H6-SUMIF(Bridge!$A:$A,"FY2025",Bridge!$C:$C))/Financials!H5,"") | I4: =IFERROR((Financials!I6-SUMIF(Bridge!$A:$A,"H1-2024",Bridge!$C:$C))/Financials!I5,"") | J4: =IFERROR((Financials!J6-SUMIF(Bridge!$A:$A,"H1-2025",Bridge!$C:$C))/Financials!J5,"") | K4: =IFERROR((Financials!K6-SUMIF(Bridge!$A:$A,"H1-2026",Bridge!$C:$C))/Financials!K5,"") | L4: EBITDA excluding one-off income / revenue
A5: Free cash flow | D5: =IFERROR(Financials!D12-Financials!D13,"") | E5: =IFERROR(Financials!E12-Financials!E13,"") | F5: =IFERROR(Financials!F12-Financials!F13,"") | G5: =IFERROR(Financials!G12-Financials!G13,"") | H5: =IFERROR(Financials!H12-Financials!H13,"") | J5: =IFERROR(Financials!J12-Financials!J13,"") | K5: =IFERROR(Financials!K12-Financials!K13,"") | L5: operating cash flow − capex
A6: Gross debt excluding leases, calculated | L6: net debt as reported + cash − lease liabilities, where the report states no total (as mvp/schema.py derive)
A7: Net debt excluding leases | E7: =(Financials!E15-Financials!E14) | F7: =(Financials!F15-Financials!F14) | G7: =(Financials!G15-Financials!G14) | H7: =(Financials!H15-Financials!H14) | K7: =(Financials!K15-Financials!K14) | L7: gross debt excluding leases − cash
A8: Net debt / EBITDA excluding one-off income | E8: =IFERROR((Financials!E15-Financials!E14)/(Financials!E6-SUMIF(Bridge!$A:$A,"FY2022",Bridge!$C:$C)),"") | F8: =IFERROR((Financials!F15-Financials!F14)/(Financials!F6-SUMIF(Bridge!$A:$A,"FY2023",Bridge!$C:$C)),"") | G8: =IFERROR((Financials!G15-Financials!G14)/(Financials!G6-SUMIF(Bridge!$A:$A,"FY2024",Bridge!$C:$C)),"") | H8: =IFERROR((Financials!H15-Financials!H14)/(Financials!H6-SUMIF(Bridge!$A:$A,"FY2025",Bridge!$C:$C)),"") | L8: net debt excluding leases / EBITDA excluding one-off income; fiscal years
A9: EBITDA excluding one-off income / net interest | D9: =IFERROR((Financials!D6-SUMIF(Bridge!$A:$A,"FY2021",Bridge!$C:$C))/Financials!D11,"") | E9: =IFERROR((Financials!E6-SUMIF(Bridge!$A:$A,"FY2022",Bridge!$C:$C))/Financials!E11,"") | F9: =IFERROR((Financials!F6-SUMIF(Bridge!$A:$A,"FY2023",Bridge!$C:$C))/Financials!F11,"") | G9: =IFERROR((Financials!G6-SUMIF(Bridge!$A:$A,"FY2024",Bridge!$C:$C))/Financials!G11,"") | H9: =IFERROR((Financials!H6-SUMIF(Bridge!$A:$A,"FY2025",Bridge!$C:$C))/Financials!H11,"") | L9: EBITDA excluding one-off income / net finance cost; fiscal years
A10: Equity ratio | D10: =IFERROR(Financials!D18/Financials!D19,"") | E10: =IFERROR(Financials!E18/Financials!E19,"") | F10: =IFERROR(Financials!F18/Financials!F19,"") | G10: =IFERROR(Financials!G18/Financials!G19,"") | H10: =IFERROR(Financials!H18/Financials!H19,"") | K10: =IFERROR(Financials!K18/Financials!K19,"") | L10: equity / total assets

Sheet Maturities
A1: Falls due | B1: Principal | C1: Leases | D1: Interest | E1: Facts | F1: Note
A2: 2026 | B2: 10.7 | E2: F1856, F1858 | F2: Unsecured retail bonds 5.0%, due 12 Dec 2026: 10.3; 4% secured loan (Caisse des Depots), current instalment due 1 Dec 2026: 0.4
A3: 2027 | B3: 5.2 | E3: F1857 | F3: Unsecured retail bonds 5.0%, due 21 Jun 2027: 5.2
A4: 2028 | B4: 58.9 | E4: F1859, F1860 | F4: Unsecured retail bonds 5.5%, due 12 Jun 2028: 24.4; Unsecured retail bonds 6.0%, due 16 Oct 2028: 34.5
A5: 2029 | B5: 83.1 | E5: F1861, F1862, F1863 | F5: Unsecured retail bonds 6.0%, due 19 Feb 2029: 27.9; Unsecured retail bonds 6.0%, due 21 Jun 2029: 33.1; Unsecured retail bonds 6.0%, due 30 Oct 2029: 22.1
A6: 2030 | B6: 110.4 | E6: F1864, F1865, F1866 | F6: Unsecured retail bonds 6.0%, due 19 Feb 2030: 36.5; Unsecured retail bonds 6.0%, due 21 Jun 2030: 34.8; Unsecured retail bonds 6.0%, due 30 Oct 2030: 39.1
A7: 2031 | B7: 89.5 | E7: F1867, F1868, F1869, F1872, F1873, F1874 | F7: Unsecured retail bonds 6.0%, due 10 Mar 2031: 32.4; Unsecured retail bonds 6.0%, due 21 Jun 2031: 36.5; 4% secured loan (Caisse des Depots), due 1 Dec 2031: 1.7; Green loan Facility A1 (EUR 55m commitment), floating EURIBOR + margin, matures 22 Jan…: 13.4; Green loan Facility A2 (CHF 23.2m commitment), floating SARON + margin, matures 22 Jan…: 1.7; Green loan Facility B (EUR 20m commitment), fixed rate, matures 22 Jan 2031, senior…: 3.8
A8: 2032 | B8: 21.6 | E8: F1870, F1871 | F8: 4% secured loan (Caisse des Depots), due 1 Dec 2032: 12.6; German Regional Tender government grant treated as interest-free loan (financial…: 9.0
A9: leases, not dated by year | C9: 76.9 | E9: F1849 | F9: lease liabilities at H1-2026
F10: principal per year of maturity, the carrying amounts of the instrument table in the H1-2026 report (S4 p43); leases are not dated by year there
F11: the 19 lines add up to 379.4, gross debt excluding leases at H1-2026 is 379.5

Sheet Debt
A1: Period | B1: Item | C1: Source | D1: Page | E1: Fact
B2: INSTRUMENTS
B3: Unsecured retail bonds 5.0%, due 12 Dec 2026, carrying EUR 10.3m (31 Dec 2025: 12.0), unsecured, not subordinated, unlisted | C3: S4 | D3: 43 | E3: F1856
B4: Unsecured retail bonds 5.0%, due 21 Jun 2027, EUR 5.2m (31 Dec 2025: 7.3) | C4: S4 | D4: 43 | E4: F1857
B5: 4% secured loan (Caisse des Depots), current instalment due 1 Dec 2026, EUR 0.4m | C5: S4 | D5: 43 | E5: F1858
B6: Unsecured retail bonds 5.5%, due 12 Jun 2028, EUR 24.4m | C6: S4 | D6: 43 | E6: F1859
B7: Unsecured retail bonds 6.0%, due 16 Oct 2028, EUR 34.5m | C7: S4 | D7: 43 | E7: F1860
B8: Unsecured retail bonds 6.0%, due 19 Feb 2029, EUR 27.9m | C8: S4 | D8: 43 | E8: F1861
B9: Unsecured retail bonds 6.0%, due 21 Jun 2029, EUR 33.1m | C9: S4 | D9: 43 | E9: F1862
B10: Unsecured retail bonds 6.0%, due 30 Oct 2029, EUR 22.1m | C10: S4 | D10: 43 | E10: F1863
B11: Unsecured retail bonds 6.0%, due 19 Feb 2030, EUR 36.5m | C11: S4 | D11: 43 | E11: F1864
B12: Unsecured retail bonds 6.0%, due 21 Jun 2030, EUR 34.8m | C12: S4 | D12: 43 | E12: F1865
B13: Unsecured retail bonds 6.0%, due 30 Oct 2030, EUR 39.1m | C13: S4 | D13: 43 | E13: F1866
B14: Unsecured retail bonds 6.0%, due 10 Mar 2031, EUR 32.4m, issued Feb-Mar 2026 (30.1 new money, 2.3 extended) | C14: S4 | D14: 43 | E14: F1867
... B63: 4% secured loan from Caisse des Dépôts maturing 01/12/2032, EUR 1,921k drawn in 2023 | C63: S1 | D63: 136 | E63: F166
B64: COVENANTS AND TERMS
B65: covenant: minimum tangible equity and minimum tangible equity to total assets (bank guarantee facility, Fastned B.V. company level); formula as defined: tangible equity; tangible equity divided by total assets; threshold: not disclosed; direction: min; test frequency: quarterly | C65: S3 | D65: 184 | E65: F1686
B66: Retail bonds: no security and no covenants that could require Fastned to repay. | C66: S4 | D66: 44 | E66: F1876
B67: Green loan facility: secured, senior, subject to financial covenants first tested on 31 December 2029. | C67: S4 | D67: 44 | E67: F1877
B68: Bank guarantee facility (EUR 20m): all financial covenants removed in H1 2026; uncommitted and unsecured. | C68: S4 | D68: 48 | E68: F1878
B69: The unsecured bonds carry no financial covenants that could require Fastned to repay the loans and no security. | C69: S3 | D69: 173 | E69: F1221
B70: Bank guarantee facility covenants: Fastned B.V. as borrower must maintain a minimum level of tangible equity and a minimum ratio of tangible equity to total assets; tested quarterly by management; complied at 31 Dec 2025. | C70: S3 | D70: 184 | E70: F1222
B71: TICO Financing contains financial covenants including leverage and interest cover tests and restrictions on additional indebtedness and distributions; thresholds not disclosed. | C71: S3 | D71: 195 | E71: F1223
B72: Bonds carry no security and no covenants that could require Fastned to repay any of the loans. | C72: S2 | D72: 147 | E72: F634
B73: No covenants apply to the bonds that could require early repayment; bonds are unsecured. | C73: S1 | D73: 136 | E73: F167
B74: term: holders (retail bonds); value: thousands of retail investors in the Netherlands and Belgium, more than 12,000 bondholders | C74: S4 | D74: 12 | E74: F2041
B75: term: rate type (retail bonds 2026 series); value: fixed 6% per annum, payable quarterly in arrears | C75: S4 | D75: 44 | E75: F2042
B76: term: call; value: Group may repay all or part of outstanding bonds at any time where the Final Terms of the series allow early redemption | C76: S4 | D76: 44 | E76: F2043
... B106: term: holders; value: retail investors (retail bond transactions, marketing for new bond issuances) | C106: S1 | D106: 199 | E106: F471

Sheet Guidance
A1: Year | B1: Metric | C1: Guidance as stated | D1: Reported | E1: Facts

Sheet Management
A1: Topic | B1: Fact | C1: Fact id
A2: person: Victor van Dijk | B2: VP Strategy, appointed March 2026. | C2: F1893
A3: person: Michiel Langezaal | B3: Co-founder and CEO, Management Board; President of ChargeUp Europe. | C3: F1894
A4: person: Francoise Poggi | B4: Chief Operating Officer, Management Board. | C4: F1895
A5: person: Remco Samuels | B5: CFO a.i. since March 2026 (not a Management Board signatory of the interim statements). | C5: F1896
A6: person: Patricia Allam | B6: Head of Funding and Investor Relations. | C6: F1897
A7: person: Matt Ersin | B7: Director of Government and Public Affairs; elected first Chair of the Green Industrial Grids Association (GIGA) in 2025. | C7: F1263
A8: person: Martijn Repko | B8: Country Director Netherlands (as of the 2025 annual report). | C8: F1264
A9: person: Pierre Courgeon | B9: Country Director France (as of the 2025 annual report). | C9: F1265
A10: owners | B10: Wilhelmina-Dok B.V. (Bart Lubbers) holds 36.7% of outstanding certificates of shares at end 2025 (2024: 36.7%). | C10: F1508
A11: owners | B11: Carraig Aonair Holding B.V. (Michiel Langezaal) holds 21.3% of outstanding certificates of shares at end 2025 (2024: 21.3%). | C11: F1509
A12: owners | B12: Breesaap B.V. holds 5.8% of the shares in Fastned B.V.; Bart Lubbers has a 33% share in Breesaap B.V. | C12: F1510
... A90: board | B90: name: Victor van Dijk; body: management; role: CFO | C90: F297

Sheet Risks
A1: Period | B1: Risk as the company states it | C1: Source | D1: Page | E1: Fact
B2: Operating cash flow H1 2026 includes EUR -6.3m timing of payments from the German highway authority and EUR -5.3m higher inventory from the delayed Q1 e-credit sale. | C2: S4 | D2: 19 | E2: F1879
B3: Management reports no material change to the risk profile presented in the 2025 Annual Report (pages 74-84). | C3: S4 | D3: 23 | E3: F1880
B4: Area of attention: dependence on key material suppliers and third parties; geopolitical developments and critical-material availability named as supply-chain risks. | C4: S4 | D4: 23 | E4: F1881
B5: Area of attention: grid capacity constraints and permit delays affect timing of station development in an increasing number of markets; timing largely outside Fastned's control. | C5: S4 | D5: 23 | E5: F1882
B6: Area of attention: external fraud (fraudulent charge-card use, invoice fraud), exposure expected to increase with new products. | C6: S4 | D6: 23 | E6: F1883
B7: Area of attention: health and safety in construction, maintenance and operation of stations. | C7: S4 | D7: 23 | E7: F1884
B8: Area of attention: scalable risk-management and internal-control framework; company plans to strengthen the framework after H1 2026 audits. | C8: S4 | D8: 23 | E8: F1885
B9: Current interest-bearing loans and borrowings EUR 16.0m at 30 June 2026 (31 Dec 2025: 12.4) against cash of 100.7; no amounts under the green facility repayable within twelve months. | C9: S4 | D9: 27 | E9: F1886
B10: Fast Places Limited (51%) is not consolidated: shared power under the joint arrangement limits Fastned's ability to direct the relevant activities. | C10: S4 | D10: 32 | E10: F1887
B11: Directors state the 12-18 month liquidity forecasts show 'adequate funds' and adopt the going concern basis; losses in early years funded by borrowings and certificate issues via FAST Foundation. | C11: S4 | D11: 33 | E11: F1888
B12: Company states it invests in new stations, chargers and grid connections only if financing for those investments is secured. | C12: S4 | D12: 33 | E12: F1889
B13: Approximately EUR 5m of Q1 2026 Dutch e-credit sales could not be recognised at 30 June 2026 because the national government registry was not operational. | C13: S4 | D13: 35 | E13: F1890
... B105: Auditor inspected correspondence with regulators including the AFM and 'did not identify a potential non-compliance risk' with laws and regulations. | C105: S1 | D105: 181 | E105: F192

Sheet Facts
A1: fact_id | B1: block | C1: field | D1: label | E1: period | F1: value | G1: unit | H1: text | I1: source | J1: page | K1: quote | L1: status | M1: reviewer | N1: note | O1: link
A2: F001 | B2: identity | C2: legal_name | D2: Legal name | H2: Fastned B.V. | I2: S1 | J2: 177 | K2: We have audited the financial statements 2023 of Fastned B.V. | L2: ok | M2: Sam Lakmaker | O2: https://vanillabonds.com/dossier-data/pdf/fastned/fastned-2023-annual-report.pdf#page=177
A3: F002 | B3: identity | C3: legal_form | D3: Legal form | H3: Dutch B.V. (private limited company) | I3: S1 | J3: 61 | K3: Fastned B.V. (the “Company”) is a private liability company incorporated under Dutch law and listed on Euronext Amsterdam in the Netherlands. | L3: pend | O3: https://vanillabonds.com/dossier-data/pdf/fastned/fastned-2023-annual-report.pdf#page=61
A4: F003 | B4: identity | C4: legal_form | D4: Legal form | H4: Dutch B.V. (besloten vennootschap) | I4: S1 | J4: 177 | K4: We have audited the financial statements 2023 of Fastned B.V. (“Fastned” or the “Company”) based in Amsterdam. | L4: pend | O4: https://vanillabonds.com/dossier-data/pdf/fastned/fastned-2023-annual-report.pdf#page=177
A5: F004 | B5: identity | C5: registry | D5: Commercial register / registration no. | H5: KvK 54606179 | I5: S1 | J5: 97 | K5: registered with the Dutch trade register under number 54606179 | L5: pend | O5: https://vanillabonds.com/dossier-data/pdf/fastned/fastned-2023-annual-report.pdf#page=97
A6: F005 | B6: identity | C6: founded | D6: Founded | H6: 2012 | I6: S1 | J6: 8 | K6: When we founded Fastned in 2012, we were seen as pioneers and some questioned if we would ever be profitable. | L6: pend | O6: https://vanillabonds.com/dossier-data/pdf/fastned/fastned-2023-annual-report.pdf#page=8
A7: F006 | B7: identity | C7: registered_office | D7: Registered office | H7: Mondriaantoren, Amstelplein 44, Amsterdam | I7: S1 | J7: 97 | K7: The registered office is located at Mondriaantoren, floor 21 & 22, Amstelplein 44 in Amsterdam. | L7: pend | O7: https://vanillabonds.com/dossier-data/pdf/fastned/fastned-2023-annual-report.pdf#page=97
A8: F007 | B8: identity | C8: registered_office | D8: Registered office | H8: Amsterdam, Amstelplein 44, 1096 BC | I8: S1 | J8: 203 | K8: Mondriaantoren, floor 21 & 22, Amstelplein 44, 1096 BC Amsterdam | L8: pend | O8: https://vanillabonds.com/dossier-data/pdf/fastned/fastned-2023-annual-report.pdf#page=203
A9: F008 | B9: identity | C9: country | D9: Country of incorporation (ISO-2) | H9: NL | I9: S1 | J9: 177 | K9: (“Fastned” or the “Company”) based in Amsterdam. | L9: ok | M9: Sam Lakmaker | O9: https://vanillabonds.com/dossier-data/pdf/fastned/fastned-2023-annual-report.pdf#page=177
A10: F009 | B10: identity | C10: sector | D10: Sector | H10: EV fast charging station operator | I10: S1 | J10: 97 | K10: The principal activity of Fastned B.V. and subsidiaries (the Group) consist of the exploitation of fast charging facilities for fully electric and hybrid cars. | L10: pend | O10: https://vanillabonds.com/dossier-data/pdf/fastned/fastned-2023-annual-report.pdf#page=97
A11: F010 | B11: identity | C11: sector | D11: Sector | H11: EV fast-charging station construction and operation | I11: S1 | J11: 117 | K11: Construction and operating charging stations | L11: pend | O11: https://vanillabonds.com/dossier-data/pdf/fastned/fastned-2023-annual-report.pdf#page=117
A12: F011 | B12: identity | C12: sites | D12: Sites / countries of operation | H12: 297 stations, 9 countries (NL DE FR BE UK CH DK IT ES) | I12: S1 | J12: 18 | K12: Fastned is now active in nine countries. | L12: pend | O12: https://vanillabonds.com/dossier-data/pdf/fastned/fastned-2023-annual-report.pdf#page=18
A13: F012 | B13: identity | C13: sites | D13: Sites / countries of operation | H13: Seven countries of operation | I13: S1 | J13: 122 | K13: The Group operates in seven countries. | L13: pend | O13: https://vanillabonds.com/dossier-data/pdf/fastned/fastned-2023-annual-report.pdf#page=122
A14: F013 | B14: identity | C14: sites | D14: Sites / countries of operation | H14: Avg FTE 2023: NL 107, DE 17, FR 15, BE 14, UK 12, CH 4, IT/ES/DK 1 | I14: S1 | J14: 123 | K14: In the Netherlands, the average number of employees was 107 (2022: 75). The other countries are split as follow: Belgium 14 (2022: 6), Switzerland 4 (2022: 2), Germany 17 (2022: 12), France 15 | L14: pend | O14: https://vanillabonds.com/dossier-data/pdf/fastned/fastned-2023-annual-report.pdf#page=123
A15: F014 | B15: identity | C15: employees | D15: Employees (FTE, period end) | E15: FY2022 | F15: 146 | H15: Headcount at year-end 2022; FTE not stated. | I15: S1 | J15: 31 | K15: We added 76 people to the team, as our organisation grew from 146 to 222 employees by year-end, with an average age of 35, ranging from 23 to 61. | L15: pend | N15: conflict: S1·p31 146 vs S1·p123 114 | O15: https://vanillabonds.com/dossier-data/pdf/fastned/fastned-2023-annual-report.pdf#page=31
A16: F015 | B16: identity | C16: employees | D16: Employees (FTE, period end) | E16: FY2022 | F16: 114 | H16: Average number of FTEs of the Group in 2022 (average, not period end) | I16: S1 | J16: 123 | K16: In 2023, the average number of FTEs of the Group was 172 (2022 : 114). | L16: pend | N16: conflict: S1·p31 146 vs S1·p123 114 | O16: https://vanillabonds.com/dossier-data/pdf/fastned/fastned-2023-annual-report.pdf#page=123
A17: F016 | B17: identity | C17: employees | D17: Employees (FTE, period end) | E17: FY2023 | F17: 222 | H17: Headcount at year-end 2023 (204 full-time, 18 part-time); FTE not stated. | I17: S1 | J17: 31 | K17: We added 76 people to the team, as our organisation grew from 146 to 222 employees by year-end, with an average age of 35, ranging from 23 to 61. | L17: pend | N17: conflict: S1·p31 222 vs S1·p123 172 vs S2·p134 172 | O17: https://vanillabonds.com/dossier-data/pdf/fastned/fastned-2023-annual-report.pdf#page=31
A18: F017 | B18: identity | C18: employees | D18: Employees (FTE, period end) | E18: FY2023 | F18: 172 | H18: Average number of FTEs of the Group in 2023 (average, not period end) | I18: S1 | J18: 123 | K18: In 2023, the average number of FTEs of the Group was 172 (2022 : 114). | L18: pend | N18: conflict: S1·p31 222 vs S1·p123 172 vs S2·p134 172 | O18: https://vanillabonds.com/dossier-data/pdf/fastned/fastned-2023-annual-report.pdf#page=123
A19: F018 | B19: identity | C19: ownership | D19: Ownership / UBO | H19: FAST holds all shares, DRs listed; Schroders >=10% of DRs | I19: S1 | J19: 64 | K19: FAST holds all shares of the Company (including those previously held by the founders and other major shareholders) and issues depository receipts (DRs) for these shares to investors and founders. | L19: pend | O19: https://vanillabonds.com/dossier-data/pdf/fastned/fastned-2023-annual-report.pdf#page=64
A20: F019 | B20: identity | C20: ownership | D20: Ownership / UBO | H20: Shares held by FAST (Fastned Administratie Stichting) | I20: S1 | J20: 118 | K20: Shares in Fastned B.V. are held by FAST (Fastned Administratie Stichting), Amsterdam. | L20: pend | O20: https://vanillabonds.com/dossier-data/pdf/fastned/fastned-2023-annual-report.pdf#page=118
A21: F020 | B21: identity | C21: ownership | D21: Ownership / UBO | H21: Wilhelmina-Dok B.V. (Bart Lubbers) 37.0% of DRs (2022: 39.2%) | I21: S1 | J21: 118 | K21: Wilhelmina-Dok B.V. (Bart Lubbers) 37.0 39.2 | L21: pend | O21: https://vanillabonds.com/dossier-data/pdf/fastned/fastned-2023-annual-report.pdf#page=118
A22: F021 | B22: identity | C22: ownership | D22: Ownership / UBO | H22: Carraig Aonair Holding B.V. (Langezaal) 21.5% (2022: 23.5%) | I22: S1 | J22: 118 | K22: Carraig Aonair Holding B.V. (Michiel Langezaal) 21.5 23.5 | L22: pend | O22: https://vanillabonds.com/dossier-data/pdf/fastned/fastned-2023-annual-report.pdf#page=118
A23: F022 | B23: identity | C23: ownership | D23: Ownership / UBO | H23: Breesaap B.V. 5.9% of shares; Bart Lubbers holds 33% of Breesaap | I23: S1 | J23: 118 | K23: Furthermore, Bart Lubbers has a 33% share in Breesaap B.V. Breesaap B.V. has 5.9% of shares in Fastned B.V. | L23: pend | O23: https://vanillabonds.com/dossier-data/pdf/fastned/fastned-2023-annual-report.pdf#page=118
A24: F023 | B24: identity | C24: listing | D24: Listings (equity, bonds) | H24: DRs on Euronext Amsterdam; retail bonds EUR 159.9m | I24: S1 | J24: 64 | K24: All DRs (100% of the Fastned share capital) are listed on Euronext Amsterdam. | L24: pend | O24: https://vanillabonds.com/dossier-data/pdf/fastned/fastned-2023-annual-report.pdf#page=64
A25: F024 | B25: identity | C25: listing | D25: Listings (equity, bonds) | H25: Bonds not registered on any exchange | I25: S1 | J25: 136 | K25: The bonds are not subordinated and trading is very limited as they are not registered on any exchange. | L25: pend | O25: https://vanillabonds.com/dossier-data/pdf/fastned/fastned-2023-annual-report.pdf#page=136
A26: F025 | B26: identity | C26: listing | D26: Listings (equity, bonds) | H26: Depositary receipts listed on Euronext; bonds unlisted | I26: S1 | J26: 150 | K26: Share price at Euronext (€) 34.18 | L26: pend | O26: https://vanillabonds.com/dossier-data/pdf/fastned/fastned-2023-annual-report.pdf#page=150
A27: F026 | B27: identity | C27: auditor | D27: Auditor | H27: BDO Audit & Assurance B.V. | I27: S1 | J27: 63 | K27: BDO Audit & Assurance B.V. was appointed as the external independent auditor for the financial years 2023 and 2024. | L27: pend | O27: https://vanillabonds.com/dossier-data/pdf/fastned/fastned-2023-annual-report.pdf#page=63
A28: F027 | B28: identity | C28: auditor | D28: Auditor | H28: BDO Audit & Assurance B.V. (2022: Deloitte Accountants B.V.) | I28: S1 | J28: 156 | K28: Group auditor for 2023 is BDO Audit & Assurance B.V. (2022: Deloitte Accountants B.V.). | L28: pend | O28: https://vanillabonds.com/dossier-data/pdf/fastned/fastned-2023-annual-report.pdf#page=156
A29: F028 | B29: identity | C29: audit_opinion | D29: Audit opinion | E29: FY2023 | H29: unqualified | I29: S1 | J29: 78 | K29: Attached to these statements is the unqualified independent auditor’s report from BDO Audit & Assurance B.V.. | L29: pend | O29: https://vanillabonds.com/dossier-data/pdf/fastned/fastned-2023-annual-report.pdf#page=78
A30: F029 | B30: identity | C30: audit_opinion | D30: Audit opinion | E30: FY2023 | H30: unqualified; consolidated statements give a true and fair view under EU-IFRS and Part 9 Book 2 DCC; no emphasis of matter | I30: S1 | J30: 178 | K30: In our opinion, the accompanying consolidated financial statements give a true and fair view of the financial position of Fastned B.V. as at 31 December 2023 | L30: pend | O30: https://vanillabonds.com/dossier-data/pdf/fastned/fastned-2023-annual-report.pdf#page=178
A31: F030 | B31: identity | C31: accounting_standard | D31: Accounting standard | H31: IFRS (EU) and Part 9 Book 2 Dutch Civil Code | I31: S1 | J31: 97 | K31: prepared in accordance with International Financial Reporting Standards (IFRS) as adopted by the European Union (EU) and also comply with the financial reporting requirements included in Part 9 | L31: pend | O31: https://vanillabonds.com/dossier-data/pdf/fastned/fastned-2023-annual-report.pdf#page=97
A32: F031 | B32: identity | C32: accounting_standard | D32: Accounting standard | H32: EU-IFRS and Part 9 of Book 2 Dutch Civil Code | I32: S1 | J32: 160 | K32: These financial statements have been prepared in accordance with International Financial Reporting Standards (IFRSs) as adopted by the European Union (EU) | L32: pend | O32: https://vanillabonds.com/dossier-data/pdf/fastned/fastned-2023-annual-report.pdf#page=160
A33: F032 | B33: identity | C33: fiscal_year_end | D33: Fiscal year end | H33: 31 December | I33: S1 | J33: 160 | K33: for the year ended 31 December 2023 | L33: pend | O33: https://vanillabonds.com/dossier-data/pdf/fastned/fastned-2023-annual-report.pdf#page=160
A34: F033 | B34: business | C34: business_fact | D34: Business fact | H34: 2023 volumes: 99.6 GWh sold (+92%), 4.0 million charging sessions (+74%), 1,714 chargers (+39%), 297 stations (+55), 755,289 active customers (+246%). | I34: S1 | J34: 4 | K34: Volume of energy sold 99.6 GWh +92% vs. 2022 | L34: pend | O34: https://vanillabonds.com/dossier-data/pdf/fastned/fastned-2023-annual-report.pdf#page=4
A35: F034 | B35: business | C35: business_fact | D35: Business fact | H35: Station uptime above 99%; Google Maps rating 4.4/5; Net Promoter Score 60 in 2023. | I35: S1 | J35: 19 | K35: Our rating of 4.4/5 on Google Maps and our 2023 Net Promoter Score of 60 are evidence that our charging experience is highly valued by our customers. | L35: pend | O35: https://vanillabonds.com/dossier-data/pdf/fastned/fastned-2023-annual-report.pdf#page=19
A36: F035 | B36: business | C36: business_fact | D36: Business fact | H36: Awards 2023: Chargemap most reliable network in Europe (390,000 reviews), ZapMap best en-route public charging network UK, Autoblog favourite fast charging network NL. | I36: S1 | J36: 19 | K36: We've been named the 'best en-route public charging network' by ZapMap in the UK and the 'favourite fast charging network' by Autoblog in the Netherlands for two years in a row. | L36: pend | O36: https://vanillabonds.com/dossier-data/pdf/fastned/fastned-2023-annual-report.pdf#page=19
A37: F036 | B37: business | C37: business_fact | D37: Business fact | H37: Proprietary software platform Revolt runs network operations; app rated 4.7/5 (Apple) and 4.6/5 (Google Play); Apple CarPlay and Android Auto added in 2023. | I37: S1 | J37: 20 | K37: Revolt, our software platform developed in-house, forms the heart of our operations. | L37: pend | O37: https://vanillabonds.com/dossier-data/pdf/fastned/fastned-2023-annual-report.pdf#page=20
A38: F037 | B38: business | C38: business_fact | D38: Business fact | H38: Stations are designed, built, operated and maintained in-house; 55 new stations across seven countries in 2023; grid congestion slowed construction in NL, FR, BE and UK. | I38: S1 | J38: 21 | K38: Grid congestion is another factor that has slowed our construction pace in the Netherlands, France, Belgium and in the United Kingdom. | L38: pend | O38: https://vanillabonds.com/dossier-data/pdf/fastned/fastned-2023-annual-report.pdf#page=21
A39: F038 | B39: business | C39: business_fact | D39: Business fact | H39: Employees: 93 new hires and 17 leavers in 2023, turnover 9% (2022: 11%); 18 workers who are not employees; 38 nationalities; women 40% of workforce. | I39: S1 | J39: 32 | K39: This is backed up by our turnover of 9% in 2023, which is a decrease from 11% in the previous year. | L39: pend | O39: https://vanillabonds.com/dossier-data/pdf/fastned/fastned-2023-annual-report.pdf#page=32
A40: F039 | B40: business | C40: business_fact | D40: Business fact | H40: Operational EBITDA (gross profit from charging less network operation costs, non-IFRS) EUR 23.8m in 2023, 8.1m in 2022, 2.4m in 2021; margin 39% in 2023 (+17 pp). | I40: S1 | J40: 36 | K40: Operational EBITDA 23.8 8.1 2.4 194 % | L40: pend | O40: https://vanillabonds.com/dossier-data/pdf/fastned/fastned-2023-annual-report.pdf#page=36
...

Sheet Documents
A1: Source | B1: Kind | C1: Period | D1: Date | E1: Origin | F1: Audited | G1: Pages | H1: Link
A2: S1 | B2: annual report | C2: FY2023 | D2: 2024-03-27 | E2: Fastned B.V. | F2: TRUE | G2: 203 | H2: https://vanillabonds.com/dossier-data/pdf/fastned/fastned-2023-annual-report.pdf
A3: S2 | B3: annual report | C3: FY2024 | D3: 2025-03-27 | E3: Fastned B.V. | F3: TRUE | G3: 207 | H3: https://vanillabonds.com/dossier-data/pdf/fastned/fastned-2024-annual-report.pdf
A4: S3 | B4: annual report | C4: FY2025 | D4: 2026-03-19 | E4: Fastned B.V. | F4: TRUE | G4: 246 | H4: https://vanillabonds.com/dossier-data/pdf/fastned/fastned-2025-annual-report.pdf
A5: S4 | B5: interim report | C5: H1-2026 | D5: 2026-08-13 | E5: Fastned B.V. (Management Board) | F5: FALSE | G5: 52 | H5: https://vanillabonds.com/dossier-data/pdf/fastned/fastned-h1-2026-interim-report.pdf
