Workbook

Sheet README
A1: Item | B1: Value
A2: Issuer | B2: Katjes International GmbH & Co. KG
A3: Data as of | B3: H1-2026
A4: Written | B4: 2026-10-22
A5: Units | B5: EUR m unless stated; days and headcount as counts; ratios as decimals
A6: Signs | B6: profits positive, losses negative; net interest = net finance cost, positive; capex and D&A positive
A7: Periods | B7: FY2025 = fiscal year ending in 2025; H1-2026 = half-year to 30 June 2026; FY2027E = a plan year or an amount falling due then (company figures)
A8: Record | B8: one value per field and period: approved before pending, audited before unaudited, the later report wins where restated (mvp/screen.py)
A9: Status | B9: ok = approved by a named reviewer; rep = management representation, attested by a named officer; pend = extracted, pending review; rej = rejected; grey cell = pending, gold cell = management representation
A10: Sources | B10: every number links to its row in Facts; the row links to the page of the published PDF or to the web source
A11: Formulas | B11: Ratios are live Excel formulas on the Financials cells, the same formulas as the platform; one-off income = the items in Bridge
A12: Scope | B12: facts and arithmetic on printed formulas only: no rating, no score, no recommendation. Demo built from the company's public reports.

Sheet Financials
A1: EUR m unless stated | B1: FY2019 | C1: FY2020 | D1: FY2021 | E1: FY2022 | F1: FY2023 | G1: FY2024 | H1: FY2025 | I1: FY2026 | J1: H1-2025 | K1: H1-2026 | L1: FY2024E | M1: FY2025E | N1: FY2026E | O1: FY2027E | P1: FY2027E-FY2029E | Q1: FY2028E
A2: Identity
A3: Employees (FTE, period end) | E3: 980 | F3: 998 | G3: 1097 | H3: 1648 | J3: 1118 | K3: 1787
A4: Historical financials and quality of earnings
A5: Revenue | B5: 210 | C5: 218 | D5: 255 | E5: 295 | F5: 377 | G5: 392.6 | H5: 503 | J5: 164.8 | K5: 256 | M5: 400
A6: EBITDA (as reported) | B6: 23 | C6: 25 | D6: 41 | E6: 37 | F6: 40.8 | G6: 44.8 | H6: 98.8 | J6: 13.9 | K6: 15.8
A7: EBIT / operating result | E7: 22.2 | F7: 22.5 | G7: 25 | H7: 71.1 | J7: 3.7 | K7: -6.8
A8: Net result | E8: 14.8 | F8: 10.2 | G8: 3.2 | H8: 53.2 | J8: -1 | K8: -15.9
A9: Depreciation & amortisation | E9: 15.1 | F9: 18.1 | G9: 19.8 | H9: 27.2
A10: Net finance cost | E10: 6.4 | F10: 11.4 | G10: 11.6 | H10: 19.2 | J10: 4.1 | K10: 11.2
A11: Cash flow from operating activities | E11: 10.4 | F11: 31.8 | G11: 45.6 | H11: 19.1 | J11: -9.8 | K11: 1.1
A12: Capex (PP&E + intangibles) | E12: 8 | F12: 14.6 | G12: 18.8 | H12: 19.6 | J12: 7 | K12: 8.3
A13: Cash & equivalents | E13: 35.5 | F13: 58.4 | G13: 54 | H13: 146.8 | J13: 38.4 | K13: 74.1
A14: Gross financial debt (bonds + loans, excl. leases) | E14: 173.5 | F14: 185.1 | G14: 176.2
A15: Lease liabilities | E15: 6.4 | F15: 6.8 | G15: 13.2 | H15: 74.7 | K15: 85.8
A16: Net debt (as reported) | E16: 138 | F16: 133.5 | G16: 135.4 | H16: 206
A17: Total equity | B17: 137.9 | C17: 139.5 | D17: 141.4 | E17: 167 | F17: 176 | G17: 176.2 | H17: 266.9 | J17: 175.3 | K17: 255.1
A18: Total assets | E18: 441.4 | F18: 477.6 | G18: 491.7 | H18: 812.3 | K18: 850.9
A19: Days from year end to filing of the accounts | F19: 87 | G19: 99 | H19: 92 | K19: 70
A20: Income taxes paid (cash flow statement) | E20: 2.6 | F20: 2.5 | G20: 2.5 | H20: 0.6 | J20: 0.3 | K20: 0.9
A21: Management
A22: Revenue as budgeted for that year (management plan at the time) | H22: 400 | I22: 650 | N22: 650
A23: Transaction, plan, projections and downside
A24: Debt principal falling due in the period | G24: 35.2 | L24: 35.2 | M24: 37.4 | N24: 74.3 | O24: 30.7 | P24: 136 | Q24: 185

Sheet Bridge
A1: Period | B1: One-off income inside EBITDA, as itemised in the reports | C1: EUR m counted | D1: Fact | E1: Rule
A2: FY2022 | B2: item: purchase price allocation effect (negative goodwill) oral care business recognised in other operating income at initial consolidation 7 Dec 2022; amount: 10.3; recurrence: 2022 | D2: F227 | E2: listed, not counted (10.3): may be part of the larger item counted
A3: FY2022 | B3: item: recognition of negative goodwill in profit or loss (other operating income); amount: 24.4; recurrence: 2022 only (2023: 0.0) | C3: 24.4 | D3: F228 | E3: counted
A4: FY2025 | B4: item: badwill from initial consolidation of Bogner (other operating income); amount: 35.1; recurrence: none | C4: 35.1 | D4: F837 | E4: counted
A5: FY2025 | B5: item: gain on disposal of the 23% CPK minority interest (other operating income); amount: 20.1; recurrence: none | C5: 20.1 | D5: F838 | E5: counted
A6: H1-2026 | B6: item: positive results from purchase price allocations in other operating result; amount: 13.8; recurrence: none in H1-2025 | D6: F1180 | E6: listed, not counted (13.8): total of the items counted
A7: H1-2026 | B7: item: badwill on the Graze acquisition, recognised in other operating income (preliminary PPA); amount: 11.2; recurrence: none stated | C7: 11.2 | D7: F1183 | E7: counted
A8: H1-2026 | B8: item: badwill on the Pastificio Plin acquisition, recognised in other operating income; amount: 2.6; recurrence: none stated | C8: 2.6 | D8: F1184 | E8: counted

Sheet Ratios
A1: Live formulas on Financials | B1: FY2019 | C1: FY2020 | D1: FY2021 | E1: FY2022 | F1: FY2023 | G1: FY2024 | H1: FY2025 | I1: H1-2025 | J1: H1-2026 | K1: Formula
A2: One-off income inside EBITDA | B2: =SUMIF(Bridge!$A:$A,"FY2019",Bridge!$C:$C) | C2: =SUMIF(Bridge!$A:$A,"FY2020",Bridge!$C:$C) | D2: =SUMIF(Bridge!$A:$A,"FY2021",Bridge!$C:$C) | E2: =SUMIF(Bridge!$A:$A,"FY2022",Bridge!$C:$C) | F2: =SUMIF(Bridge!$A:$A,"FY2023",Bridge!$C:$C) | G2: =SUMIF(Bridge!$A:$A,"FY2024",Bridge!$C:$C) | H2: =SUMIF(Bridge!$A:$A,"FY2025",Bridge!$C:$C) | I2: =SUMIF(Bridge!$A:$A,"H1-2025",Bridge!$C:$C) | J2: =SUMIF(Bridge!$A:$A,"H1-2026",Bridge!$C:$C) | K2: SUM of Bridge for the period
A3: EBITDA excluding one-off income | B3: =(Financials!B6-SUMIF(Bridge!$A:$A,"FY2019",Bridge!$C:$C)) | C3: =(Financials!C6-SUMIF(Bridge!$A:$A,"FY2020",Bridge!$C:$C)) | D3: =(Financials!D6-SUMIF(Bridge!$A:$A,"FY2021",Bridge!$C:$C)) | E3: =(Financials!E6-SUMIF(Bridge!$A:$A,"FY2022",Bridge!$C:$C)) | F3: =(Financials!F6-SUMIF(Bridge!$A:$A,"FY2023",Bridge!$C:$C)) | G3: =(Financials!G6-SUMIF(Bridge!$A:$A,"FY2024",Bridge!$C:$C)) | H3: =(Financials!H6-SUMIF(Bridge!$A:$A,"FY2025",Bridge!$C:$C)) | I3: =(Financials!J6-SUMIF(Bridge!$A:$A,"H1-2025",Bridge!$C:$C)) | J3: =(Financials!K6-SUMIF(Bridge!$A:$A,"H1-2026",Bridge!$C:$C)) | K3: EBITDA as reported − one-off income
A4: EBITDA margin excluding one-off income | B4: =IFERROR((Financials!B6-SUMIF(Bridge!$A:$A,"FY2019",Bridge!$C:$C))/Financials!B5,"") | C4: =IFERROR((Financials!C6-SUMIF(Bridge!$A:$A,"FY2020",Bridge!$C:$C))/Financials!C5,"") | D4: =IFERROR((Financials!D6-SUMIF(Bridge!$A:$A,"FY2021",Bridge!$C:$C))/Financials!D5,"") | E4: =IFERROR((Financials!E6-SUMIF(Bridge!$A:$A,"FY2022",Bridge!$C:$C))/Financials!E5,"") | F4: =IFERROR((Financials!F6-SUMIF(Bridge!$A:$A,"FY2023",Bridge!$C:$C))/Financials!F5,"") | G4: =IFERROR((Financials!G6-SUMIF(Bridge!$A:$A,"FY2024",Bridge!$C:$C))/Financials!G5,"") | H4: =IFERROR((Financials!H6-SUMIF(Bridge!$A:$A,"FY2025",Bridge!$C:$C))/Financials!H5,"") | I4: =IFERROR((Financials!J6-SUMIF(Bridge!$A:$A,"H1-2025",Bridge!$C:$C))/Financials!J5,"") | J4: =IFERROR((Financials!K6-SUMIF(Bridge!$A:$A,"H1-2026",Bridge!$C:$C))/Financials!K5,"") | K4: EBITDA excluding one-off income / revenue
A5: Free cash flow | E5: =IFERROR(Financials!E11-Financials!E12,"") | F5: =IFERROR(Financials!F11-Financials!F12,"") | G5: =IFERROR(Financials!G11-Financials!G12,"") | H5: =IFERROR(Financials!H11-Financials!H12,"") | I5: =IFERROR(Financials!J11-Financials!J12,"") | J5: =IFERROR(Financials!K11-Financials!K12,"") | K5: operating cash flow − capex
A6: Net debt excluding leases | E6: =(Financials!E14-Financials!E13) | F6: =(Financials!F14-Financials!F13) | G6: =(Financials!G14-Financials!G13) | K6: gross debt excluding leases − cash
A7: Net debt / EBITDA excluding one-off income | E7: =IFERROR((Financials!E14-Financials!E13)/(Financials!E6-SUMIF(Bridge!$A:$A,"FY2022",Bridge!$C:$C)),"") | F7: =IFERROR((Financials!F14-Financials!F13)/(Financials!F6-SUMIF(Bridge!$A:$A,"FY2023",Bridge!$C:$C)),"") | G7: =IFERROR((Financials!G14-Financials!G13)/(Financials!G6-SUMIF(Bridge!$A:$A,"FY2024",Bridge!$C:$C)),"") | K7: net debt excluding leases / EBITDA excluding one-off income; fiscal years
A8: EBITDA excluding one-off income / net interest | E8: =IFERROR((Financials!E6-SUMIF(Bridge!$A:$A,"FY2022",Bridge!$C:$C))/Financials!E10,"") | F8: =IFERROR((Financials!F6-SUMIF(Bridge!$A:$A,"FY2023",Bridge!$C:$C))/Financials!F10,"") | G8: =IFERROR((Financials!G6-SUMIF(Bridge!$A:$A,"FY2024",Bridge!$C:$C))/Financials!G10,"") | H8: =IFERROR((Financials!H6-SUMIF(Bridge!$A:$A,"FY2025",Bridge!$C:$C))/Financials!H10,"") | K8: EBITDA excluding one-off income / net finance cost; fiscal years
A9: Equity ratio | E9: =IFERROR(Financials!E17/Financials!E18,"") | F9: =IFERROR(Financials!F17/Financials!F18,"") | G9: =IFERROR(Financials!G17/Financials!G18,"") | H9: =IFERROR(Financials!H17/Financials!H18,"") | J9: =IFERROR(Financials!K17/Financials!K18,"") | K9: equity / total assets

Sheet Debt
A1: Period | B1: Item | C1: Source | D1: Page | E1: Fact
A2: FY2026E | B2: principal falling due: 74.3 | C2: S3 | D2: 57 | E2: F754
A3: FY2027E | B3: principal falling due: 30.7 | C3: S3 | D3: 57 | E3: F755
A4: FY2028E | B4: principal falling due: 185.0 | C4: S3 | D4: 57 | E4: F756
B5: INSTRUMENTS
B6: Corporate bond 2023/2028, EUR 200.0m nominal after the EUR 15m increase in May 2026 (Missoni); carrying amount 200.0, fair value 191.3 at 30 June 2026; coupon not stated in this report. | C6: S5 | D6: 21 | E6: F1091
B7: Acquisition financing (long-term bank loans) for part of the Graze purchase price, amount not stated separately. | C7: S5 | D7: 25 | E7: F1092
B8: Non-current interest-bearing loans EUR 51.0m at 30 June 2026 (amortised cost, fair value 51.0); includes acquisition financing for part of the Graze purchase price. | C8: S5 | D8: 42 | E8: F1093
B9: Current interest-bearing loans EUR 68.1m at 30 June 2026, increased by new short-term credit lines drawn during the period. | C9: S5 | D9: 42 | E9: F1094
B10: Bond 2023/2028: senior unsecured bearer bond, target EUR 110m (minimum EUR 80m), fixed coupon marketed at 6.25-7.50% p.a. paid semi-annually, issued 21 September 2023, due 21 September 2028, ISIN NO0012888769, denomination EUR 1,000. | C10: S4 | D10: 1 | E10: F950
B11: Bond 2019/2024 (ISIN DE000A2TST99): outstanding at the time of the term sheet and to be refinanced from the proceeds of the 2023/2028 bond; amount and coupon not stated here. | C11: S4 | D11: 1 | E11: F951
B12: Liabilities to banks total EUR 72.0m at 31 Dec 2025 (2024: 50.4) within financial liabilities of 352.8. | C12: S3 | D12: 58 | E12: F686
B13: Accrued interest liabilities relating to the bond EUR 3.5m at 31 Dec 2025 (2024: 2.1). | C13: S3 | D13: 58 | E13: F687
B14: Hire purchase liabilities EUR 8.2m at 31 Dec 2025, of which current 2.4 (2024: 6.7, current 5.5); interest expense hire purchases 0.3. | C14: S3 | D14: 58 | E14: F688
B15: Liability from the purchase option on the remaining 25% of Dulcioliva EUR 1.6m, fully recognised as exercise probability unchanged. | C15: S3 | D15: 58 | E15: F689
B16: Put option granted to Bogner non-controlling shareholders recognised as financial liability of EUR 5.5m since initial consolidation. | C16: S3 | D16: 58 | E16: F690
B17: 2023/2028 corporate bond, 6.75% fixed, issued September 2023 at EUR 115m, increased by EUR 70m in August 2025 to EUR 185.0m outstanding at 31 Dec 2025 (2024: 115.0); interest expense 2025 EUR 9.5m; no ISIN or security stated. | C17: S3 | D17: 63 | E17: F691
... B53: 2020 liquidity-support bank loan: total EUR 5.0m, EUR 1.7m outstanding at 31 Dec 2023, not from a development bank, majority secured by a state guarantee. | C53: S1 | D53: 72 | E53: F093
B54: COVENANTS AND TERMS
B55: covenant: debt incurrence test; formula: Nettoverschuldung (Net Debt) / EBITDA; threshold: 3.75x; direction: max; test frequency: on each incurrence of additional debt | C55: S4 | D55: 2 | E55: F970
B56: covenant: distribution test; formula: Nettoverschuldung (Net Debt) / EBITDA after the distribution; threshold: 3.75x; direction: max; test frequency: on each distribution to shareholders | C56: S4 | D56: 2 | E56: F971
B57: covenant: negative pledge basket; formula: liabilities secured on the assets of the issuer or group; threshold: EUR 1.0m or, if greater, 5% of EBITDA; direction: max | C57: S4 | D57: 2 | E57: F972
B58: Breach of the issuer's undertakings, or events such as non-compliance with certain financial ratios, gives bondholders termination rights, subject to cure periods and the further conditions of the bond terms. | C58: S4 | D58: 1 | E58: F952
B59: Undertakings restrict mergers or similar business combinations. | C59: S4 | D59: 1 | E59: F953
B60: Undertakings restrict disposals of assets. | C60: S4 | D60: 1 | E60: F954
B61: Undertakings restrict financial indebtedness (Financial Indebtedness). | C61: S4 | D61: 1 | E61: F955
B62: Debt incurrence test: additional financial indebtedness of the issuer is permitted only if Net Debt / EBITDA is below 3.75x. | C62: S4 | D62: 2 | E62: F956
B63: Distributions to shareholders, including repayments of and interest on shareholder loans, are permitted only if Net Debt / EBITDA remains below 3.75x after the distribution. | C63: S4 | D63: 2 | E63: F957
B64: Distributions remain permitted to the extent the shareholder bears a tax charge from its participation in the issuer. | C64: S4 | D64: 2 | E64: F958
B65: Negative pledge: the issuer and group may not grant security over their assets, with exceptions including secured liabilities of up to EUR 1m or, if greater, 5% of EBITDA. | C65: S4 | D65: 2 | E65: F959
B66: Cross default: the bonds become callable if financial liabilities of EUR 7.5m in aggregate are not paid by the issuer or group or become callable because of insolvency. | C66: S4 | D66: 2 | E66: F960
... B117: term: listing; value: Nordic ABM of the Oslo Stock Exchange, included end of January 2024 (within six months of issue) | C117: S1 | D117: 85 | E117: F322

Sheet Guidance
A1: Year | B1: Metric | C1: Guidance as stated | D1: Reported | E1: Facts
A2: FY2023 | B2: EBITDA | C2: Guidance for 2023 as stated: EBITDA margin 9–10%; actual 10.8% | D2: 40.8 · margin 10.8% | E2: F115, F368
A3: FY2023 | B3: Revenue | C3: Guidance for 2023 as stated: consolidated net sales EUR 350m–375m (raised during the year); actual 377.4 exceeded it | D3: 377.0 | E3: F114, F654
A4: FY2024 | B4: EBITDA | C4: Guidance for 2024: EBITDA margin forecast at 10% (upper end of the range, half-year 2024 report); actual margin 11.4%. | D4: 44.8 · margin 11.4% | E4: F426, F660
A5: FY2024 | B5: Revenue | C5: Guidance issued for 2024: consolidated revenues between EUR 390m and EUR 420m; actual 392.6. | D5: 392.6 | E5: F425, F655
A6: FY2025 | B6: EBITDA | C6: Guidance for 2025 as stated in the FY2024 report: EBITDA margin between 9% and 10% (no absolute figure). | D6: 98.8 · margin 19.6%; excluding one-off income 43.6, margin 8.7% | E6: F1254, F661
A7: FY2025 | B7: Revenue | C7: Guidance for 2025 was Group revenue of at least EUR 400m; actual 503.0 | D7: 503.0 | E7: F716, F656
A8: FY2026 | B8: EBITDA | C8: Guidance for 2026 as stated in the FY2025 report: EBITDA margin between 10% and 12% (no absolute figure). | D8: not yet reported | E8: F1255
A9: FY2026 | B9: Revenue | C9: Company guidance for FY2026: Group revenue of 'at least EUR 650 million', which management expects 'to meet or exceed'. | D9: not yet reported | E9: F1104

Sheet Management
A1: Topic | B1: Fact | C1: Fact id
A2: person: Stephan Milde | B2: Managing Director (CFO) since 2012; before: several years in investment banking at Deutsche Bank and Citigroup in London. | C2: F1101
A3: person: Bastian Fassin | B3: Managing Partner since 2004; until 2003 Marketing and Sales at Kraft Foods; until 2000 Roland Berger Strategy Consultants. | C3: F1102
A4: person: Tobias Bachmüller | B4: Managing Partner since 1996; until 1995 General Manager Kraft Foods (Milka); until 1992 Principal, The Boston Consulting Group. | C4: F1103
A5: owners | B5: Limited partnership capital EUR 1.0m: fixed capital shares Bastian Fassin 0.9 (2023: 0.5) and Tobias Bachmüller 0.1 (0.1); no personal guarantee, share pledge or family charter is mentioned. | C5: F503
A6: owners | B6: Limited partners' fixed capital shares: Bastian Fassin EUR 0.5m, Tobias Bachmüller EUR 0.1m (registered liability EUR 540k / EUR 60k); interest-bearing clearing accounts of the limited partners EUR 0.5m at 5.0%. | C6: F198
A7: lenders | B7: No covenant test result disclosed; management states covenant compliance is ensured through continuous monitoring of KPIs and forward-looking financial planning. | C7: F718
A8: lenders | B8: instrument: Anleihe 2019/2024 (ISIN DE000A2TST99); due: 2024; outcome: refinanced by the 2023/2028 bond as stated in its use of proceeds | C8: F969
A9: lenders | B9: instrument: 2019/2024 bond; due: 2024; outcome: refinanced early in 2023 at 100.5% by the 2023/2028 bond of EUR 115m at 6.75% | C9: F904
A10: lenders | B10: instrument: purchase-price liability for the Oral Care production site in Viersen, recognised as financial liability at 31 Dec 2023; amount: 6.4; due: 2024; outcome: repaid in 2024 | C10: F583
A11: lenders | B11: instrument: 2019/2024 corporate bond; amount: 110.0; due: 2024; outcome: refinanced early in September 2023 at 100.5% by the new 2023/2028 bond of EUR 115m at 6.75% | C11: F584
A12: changes | B12: role: CEO Bogner (subsidiary); person: Arne Freundt; joined: 2026-06-01; reason as stated: former PUMA CEO assumed leadership to develop the brand and its international expansion | C12: F1242
... A27: board | B27: name: Tobias Bachmüller; body: management; role: Managing Shareholder, shareholder of general partner Xaver Fassin International GmbH and limited partner; since: 1996; independent: no | C27: F189

Sheet Risks
A1: Period | B1: Risk as the company states it | C1: Source | D1: Page | E1: Fact
B2: Seasonality: the second half carries significantly higher revenue and is decisive for the full year; the Bogner companies reinforce this pattern. | C2: S5 | D2: 22 | E2: F1095
B3: Two instances of damage caused by third parties reduced H1-2026 operating result; the company states insurance coverage or a right of recourse 'generally exists' and expects resolution in H2-2026. | C3: S5 | D3: 23 | E3: F1096
B4: Financial result worsened to -11.2 from -4.1, attributed to the bond increase and acquisition financing for Bogner, Missoni and Graze. | C4: S5 | D4: 23 | E4: F1097
B5: Going concern: management states 'no risks threatening the Company's continued existence are identifiable at present or in the foreseeable future'. | C5: S5 | D5: 26 | E5: F1098
B6: No significant changes in opportunities and risks versus the 2025 consolidated financial statements (pages 30 to 34 of that report). | C6: S5 | D6: 26 | E6: F1099
B7: FX: cash held in GBP EUR 2.8m (0.5m) and in other currencies, mainly RUB, CHF and USD, EUR 8.6m (10.6m) at 30 June 2026; group includes Bogner Eastern Europe LLC, Moscow. | C7: S5 | D7: 41 | E7: F1100
B8: Operating cash flow fell to 19.1 (2024: 45.6), attributed among other factors to the Bogner Group's strongly seasonal working capital; inventories rose to 97.1 (51.3) and receivables to 100.6 (59.2). | C8: S3 | D8: 26 | E8: F701
B9: Management expects 'largely stable sales development' citing the low cyclicality of confectionery and body care; luxury goods (Bogner) are described as subject to 'significant risks'. | C9: S3 | D9: 30 | E9: F702
B10: FX: international raw material sourcing exposes the Group to foreign exchange risk, especially against the US dollar; USD purchases hedged with forwards (notional 92.0); RUB, GBP, USD, CAD, CHF rates applied. | C10: S3 | D10: 32 | E10: F703
B11: Group companies may be required to repay subsidies or other government grants (stated risk, no amount). | C11: S3 | D11: 32 | E11: F704
B12: Key-person risk: success depends on the expertise and experience of key management personnel and qualified employees (stated risk). | C12: S3 | D12: 32 | E12: F705
B13: Holding structure: Katjes International's earnings are primarily dependent on the results of its subsidiaries and portfolio companies, which it services for consideration. | C13: S3 | D13: 32 | E13: F706
... B51: Trade receivables of EUR 0.9m more than six months overdue were written off in full at 31 Dec 2023; impairment allowance 0.4 (2022: 1.2). | C51: S1 | D51: 70 | E51: F110

Sheet Facts
A1: fact_id | B1: block | C1: field | D1: label | E1: period | F1: value | G1: unit | H1: text | I1: source | J1: page | K1: quote | L1: status | M1: reviewer | N1: note | O1: link
A2: F001 | B2: identity | C2: legal_name | D2: Legal name | H2: Katjes International GmbH & Co. KG | I2: S1 | J2: 50 | K2: Katjes International GmbH & Co. KG (‘Katjes | L2: ok | M2: demo reviewer | O2: https://vanillabonds.com/dossier-data/pdf/katjes/katjes-2023-annual-report.pdf#page=50
A3: F002 | B3: identity | C3: legal_form | D3: Legal form | H3: German GmbH & Co. KG (limited partnership) | I3: S1 | J3: 50 | K3: is a limited partnership (Kommanditgesellschaft) | L3: ok | M3: demo reviewer | O3: https://vanillabonds.com/dossier-data/pdf/katjes/katjes-2023-annual-report.pdf#page=50
A4: F003 | B4: identity | C4: registry | D4: Commercial register / registration no. | H4: Amtsgericht Kleve HRA 1076 | I4: S1 | J4: 50 | K4: Court (Amtsgericht) under commercial register number HRA 1076 | L4: ok | M4: demo reviewer | O4: https://vanillabonds.com/dossier-data/pdf/katjes/katjes-2023-annual-report.pdf#page=50
A5: F004 | B5: identity | C5: founded | D5: Founded | H5: Established 2011 from predecessor companies | I5: S1 | J5: 9 | K5: Established in 2011 from predecessor companies, the Katjes Group consists of Katjes International GmbH & Co. | L5: ok | M5: demo reviewer | O5: https://vanillabonds.com/dossier-data/pdf/katjes/katjes-2023-annual-report.pdf#page=9
A6: F005 | B6: identity | C6: registered_office | D6: Registered office | H6: Dechant-Sprünken-Str. 53–57, 46446 Emmerich am Rhein | I6: S1 | J6: 50 | K6: Dechant-Sprünken-Str. 53–57 46446 Emmerich am Rhein Germany | L6: ok | M6: demo reviewer | O6: https://vanillabonds.com/dossier-data/pdf/katjes/katjes-2023-annual-report.pdf#page=50
A7: F006 | B7: identity | C7: country | D7: Country of incorporation (ISO-2) | H7: DE | I7: S1 | J7: 50 | K7: 46446 Emmerich am Rhein Germany | L7: ok | M7: demo reviewer | O7: https://vanillabonds.com/dossier-data/pdf/katjes/katjes-2023-annual-report.pdf#page=50
A8: F007 | B8: identity | C8: sector | D8: Sector | H8: FMCG: confectionery and personal care products | I8: S1 | J8: 81 | K8: The Katjes International Group, through its subsidiaries, is a manufacturer and supplier of FMCG | L8: ok | M8: demo reviewer | O8: https://vanillabonds.com/dossier-data/pdf/katjes/katjes-2023-annual-report.pdf#page=81
A9: F008 | B9: identity | C9: sites | D9: Sites / countries of operation | H9: Production and sales in Italy, Germany, UK, Netherlands | I9: S1 | J9: 50 | K9: were performed in the Group companies in Italy, Germany, the United Kingdom (UK) and the Netherlands. | L9: ok | M9: demo reviewer | O9: https://vanillabonds.com/dossier-data/pdf/katjes/katjes-2023-annual-report.pdf#page=50
A10: F009 | B10: identity | C10: employees | D10: Employees (FTE, period end) | E10: FY2022 | F10: 980 | H10: Average employees for the year (not period end): 980 | I10: S1 | J10: 50 | K10: The Company employed an average of 998 employees in the financial year 2023 (2022: 980) | L10: ok | M10: demo reviewer | O10: https://vanillabonds.com/dossier-data/pdf/katjes/katjes-2023-annual-report.pdf#page=50
A11: F010 | B11: identity | C11: employees | D11: Employees (FTE, period end) | E11: FY2023 | F11: 998 | H11: Average employees for the year (not period end): 998, of which 596 Germany, 373 Italy, 14 Netherlands, 15 UK | I11: S1 | J11: 50 | K11: The Company employed an average of 998 employees in the financial year 2023 (2022: 980) | L11: ok | M11: demo reviewer | O11: https://vanillabonds.com/dossier-data/pdf/katjes/katjes-2023-annual-report.pdf#page=50
A12: F011 | B12: identity | C12: ownership | D12: Ownership / UBO | H12: Bastian Fassin (EUR 540k) and Tobias Bachmüller (EUR 60k) | I12: S1 | J12: 50 | K12: partners are Bastian Fassin, with registered liability of EUR 540 thousand and Tobias Bachmüller | L12: ok | M12: demo reviewer | O12: https://vanillabonds.com/dossier-data/pdf/katjes/katjes-2023-annual-report.pdf#page=50
A13: F012 | B13: identity | C13: listing | D13: Listings (equity, bonds) | H13: Bond 2023/2028 on Nordic ABM, Oslo Stock Exchange (Jan 2024) | I13: S1 | J13: 85 | K13: the Nordic ABM of the Oslo Stock Exchange at the end of January 2024 as planned within six months of the issue | L13: ok | M13: demo reviewer | O13: https://vanillabonds.com/dossier-data/pdf/katjes/katjes-2023-annual-report.pdf#page=85
A14: F013 | B14: identity | C14: auditor | D14: Auditor | H14: EY GmbH & Co. KG Wirtschaftsprüfungsgesellschaft, Düsseldorf | I14: S1 | J14: 94 | K14: Düsseldorf, 27th March 2024 EY GmbH & Co. KG Wirtschaftsprüfungsgesellschaft | L14: ok | M14: demo reviewer | O14: https://vanillabonds.com/dossier-data/pdf/katjes/katjes-2023-annual-report.pdf#page=94
A15: F014 | B15: identity | C15: audit_opinion | D15: Audit opinion | E15: FY2023 | H15: unqualified; no reservations (Sec. 322 (3) HGB); no EoM | I15: S1 | J15: 91 | K15: Pursuant to Sec. 322 (3) Sentence 1 HGB, we declare that our audit has not led to any reservations | L15: ok | M15: demo reviewer | O15: https://vanillabonds.com/dossier-data/pdf/katjes/katjes-2023-annual-report.pdf#page=91
A16: F015 | B16: identity | C16: accounting_standard | D16: Accounting standard | H16: IFRS as adopted by the EU plus Sec. 315e (1) HGB | I16: S1 | J16: 51 | K16: (IFRS) as adopted by the EU and the supplementary provisions set out in section 315e (1) of the German Commercial Code (HGB). | L16: ok | M16: demo reviewer | O16: https://vanillabonds.com/dossier-data/pdf/katjes/katjes-2023-annual-report.pdf#page=51
A17: F016 | B17: identity | C17: fiscal_year_end | D17: Fiscal year end | H17: 31 December (calendar year) | I17: S1 | J17: 50 | K17: The financial year is the calendar year. | L17: ok | M17: demo reviewer | O17: https://vanillabonds.com/dossier-data/pdf/katjes/katjes-2023-annual-report.pdf#page=50
A18: F017 | B18: business | C18: business_fact | D18: Business fact | H18: Activities are focused on Italy, Germany, the Netherlands, the UK, Spain and France through investments in local brands. | I18: S1 | J18: 9 | K18: activities are currently focused on Italy, Germany, the Netherlands, the UK, Spain and France. | L18: ok | M18: demo reviewer | O18: https://vanillabonds.com/dossier-data/pdf/katjes/katjes-2023-annual-report.pdf#page=9
A19: F018 | B19: business | C19: business_fact | D19: Business fact | H19: Dallmann's Pharma Candy produces Dallmann's sage throat lozenges and distributes WICK cough drops in Germany. | I19: S1 | J19: 17 | K19: Throat and cough drops / distribution of ‘WICK’ cough drops | L19: ok | M19: demo reviewer | O19: https://vanillabonds.com/dossier-data/pdf/katjes/katjes-2023-annual-report.pdf#page=17
A20: F019 | B20: business | C20: business_fact | D20: Business fact | H20: Katjes International is a strategic investor for more than a decade; sister companies Katjes Fassin GmbH + Co. KG (Katjes Germany) and Katjesgreenfood GmbH & Co. KG are legally independent and outside the consolidation. | I20: S1 | J20: 26 | K20: has been operating as a strategic investor for more than a decade. Together with its sister companies Katjes Fassin GmbH + Co. KG (‘Katjes Germany’) | L20: ok | M20: demo reviewer | O20: https://vanillabonds.com/dossier-data/pdf/katjes/katjes-2023-annual-report.pdf#page=26
A21: F020 | B21: business | C21: business_fact | D21: Business fact | H21: After an acquisition the associated companies remain legally and organisationally independent and local management is kept in place. | I21: S1 | J21: 26 | K21: associated companies remain independent in legal and organisational terms, and the local management is kept in place. | L21: ok | M21: demo reviewer | O21: https://vanillabonds.com/dossier-data/pdf/katjes/katjes-2023-annual-report.pdf#page=26
A22: F021 | B22: business | C22: business_fact | D22: Business fact | H22: Research and development expenses of the subsidiaries were EUR 1.0m in 2023 (2022: EUR 1.0m). | I22: S1 | J22: 28 | K22: reporting year, the corresponding expenses amounted to EUR 1.0 million (previous year: EUR 1.0 million) | L22: ok | M22: demo reviewer | O22: https://vanillabonds.com/dossier-data/pdf/katjes/katjes-2023-annual-report.pdf#page=28
A23: F022 | B23: business | C23: business_fact | D23: Business fact | H23: Product mix 2023: sugar confectionery 41.4% of sales (2022: 43.1%), body care 23.1% (18.8%), chocolate 15.7% (18.7%), seasonal 12.4% (12.6%). | I23: S1 | J23: 32 | K23: Chocolate products accounted for 15.7% (previous year: 18.7%) and seasonal products amounted to 12.4% (previous year: 12.6%). | L23: ok | M23: demo reviewer | O23: https://vanillabonds.com/dossier-data/pdf/katjes/katjes-2023-annual-report.pdf#page=32
A24: F023 | B24: business | C24: business_fact | D24: Business fact | H24: Cost of sales EUR 295.5m = 78.3% of revenue (2022: 82.6%); gross profit EUR 81.9m, gross margin 21.7% (2022: 17.4%). | I24: S1 | J24: 32 | K24: At 78.3%, cost of sales as a percentage of revenue was below the previous year’s level (2022: 82.6%). | L24: ok | M24: demo reviewer | O24: https://vanillabonds.com/dossier-data/pdf/katjes/katjes-2023-annual-report.pdf#page=32
A25: F024 | B25: business | C25: business_fact | D25: Business fact | H25: Equity ratio 36.9% at 31 Dec 2023 (2022: 37.8%), described by management as 'stable'. | I25: S1 | J25: 34 | K25: equity ratio remained stable at 36.9% as at the reporting date (31 December 2022: 37.8%). | L25: ok | M25: demo reviewer | O25: https://vanillabonds.com/dossier-data/pdf/katjes/katjes-2023-annual-report.pdf#page=34
A26: F025 | B26: business | C26: business_fact | D26: Business fact | H26: Raw material price risks are monitored through joint purchasing with Katjes Germany and the subsidiaries; short-term price risk managed by longer-term fixed-price supplier contracts. | I26: S1 | J26: 40 | K26: Risks relating to raw material prices are monitored as part of the joint purchasing activities with Katjes Germany | L26: ok | M26: demo reviewer | O26: https://vanillabonds.com/dossier-data/pdf/katjes/katjes-2023-annual-report.pdf#page=40
A27: F026 | B27: business | C27: business_fact | D27: Business fact | H27: Cash flow from investing activities EUR -14.6m in 2023 (2022: EUR -28.8m), including the cash outflow for the N.A.E. brand; 2022 included EUR 20.9m acquisition of subsidiaries. | I27: S1 | J27: 48 | K27: Cash flow from investing activities -14.6 -28.8 | L27: ok | M27: demo reviewer | O27: https://vanillabonds.com/dossier-data/pdf/katjes/katjes-2023-annual-report.pdf#page=48
... A40: F039 | B40: business | C40: key_event | D40: Key event (M&A, financing, strategy) | H40: End of January 2024: the 2023/2028 bond, structured as a Nordic bond for the first time, was included in the Nordic ABM of the Oslo Stock Exchange within six months of issue. | I40: S1 | J40: 85 | K40: The Katjes International 2023/2028 bond, which was for the first time structured as a Nordic bond, was included in | L40: ok | M40: demo reviewer | O40: https://vanillabonds.com/dossier-data/pdf/katjes/katjes-2023-annual-report.pdf#page=85
A41: F040 | B41: financials | C41: revenue | D41: Revenue | E41: FY2019 | F41: 210 | G41: EUR m | H41: From the five-year sales chart (rounded to EUR m) | I41: S1 | J41: 7 | K41: 210 218 255 295 2019 2020 2021 2022 2023 377 | L41: ok | M41: demo reviewer | O41: https://vanillabonds.com/dossier-data/pdf/katjes/katjes-2023-annual-report.pdf#page=7
A42: F041 | B42: financials | C42: revenue | D42: Revenue | E42: FY2020 | F42: 218 | G42: EUR m | H42: From the five-year sales chart (rounded to EUR m) | I42: S1 | J42: 7 | K42: 210 218 255 295 2019 2020 2021 2022 2023 377 | L42: ok | M42: demo reviewer | O42: https://vanillabonds.com/dossier-data/pdf/katjes/katjes-2023-annual-report.pdf#page=7
A43: F042 | B43: financials | C43: revenue | D43: Revenue | E43: FY2021 | F43: 255 | G43: EUR m | H43: From the five-year sales chart (rounded to EUR m) | I43: S1 | J43: 7 | K43: 210 218 255 295 2019 2020 2021 2022 2023 377 | L43: ok | M43: demo reviewer | O43: https://vanillabonds.com/dossier-data/pdf/katjes/katjes-2023-annual-report.pdf#page=7
A44: F043 | B44: financials | C44: revenue | D44: Revenue | E44: FY2022 | F44: 294.5 | G44: EUR m | H44: Consolidated revenue | I44: S1 | J44: 43 | K44: Revenue 377.4 294.5 | L44: ok | M44: demo reviewer | O44: https://vanillabonds.com/dossier-data/pdf/katjes/katjes-2023-annual-report.pdf#page=43
A45: F044 | B45: financials | C45: revenue | D45: Revenue | E45: FY2023 | F45: 377.4 | G45: EUR m | H45: Consolidated revenue | I45: S1 | J45: 43 | K45: Revenue 377.4 294.5 | L45: ok | M45: demo reviewer | O45: https://vanillabonds.com/dossier-data/pdf/katjes/katjes-2023-annual-report.pdf#page=43
A46: F045 | B46: financials | C46: revenue | D46: Revenue | E46: FY2024E | G46: EUR m | H46: Management guidance for 2024: consolidated sales between EUR 390m and EUR 420m (range, no point figure) | I46: S1 | J46: 41 | K46: company is expecting sales of between EUR 390 million and EUR 420 million for the financial year 2024. | L46: ok | M46: demo reviewer | O46: https://vanillabonds.com/dossier-data/pdf/katjes/katjes-2023-annual-report.pdf#page=41
A47: F046 | B47: financials | C47: ebitda | D47: EBITDA (as reported) | E47: FY2019 | F47: 23 | G47: EUR m | H47: From the five-year EBITDA chart (rounded to EUR m); year order read left to right | I47: S1 | J47: 7 | K47: 23 25 17 2019 2020 2021 2022 2023 37 41 | L47: ok | M47: demo reviewer | O47: https://vanillabonds.com/dossier-data/pdf/katjes/katjes-2023-annual-report.pdf#page=7
A48: F047 | B48: financials | C48: ebitda | D48: EBITDA (as reported) | E48: FY2020 | F48: 25 | G48: EUR m | H48: From the five-year EBITDA chart (rounded to EUR m); year order read left to right | I48: S1 | J48: 7 | K48: 23 25 17 2019 2020 2021 2022 2023 37 41 | L48: ok | M48: demo reviewer | O48: https://vanillabonds.com/dossier-data/pdf/katjes/katjes-2023-annual-report.pdf#page=7
A49: F048 | B49: financials | C49: ebitda | D49: EBITDA (as reported) | E49: FY2021 | F49: 17 | G49: EUR m | H49: From the five-year EBITDA chart (rounded to EUR m); year order read left to right | I49: S1 | J49: 7 | K49: 23 25 17 2019 2020 2021 2022 2023 37 41 | L49: pend | N49: conflict: S1·p7 17.0 vs S3·p7 41.0; primary per fact agent: open - no audited statement on file carries FY2021 EBITDA, and the chart text layers in S1 p7, S2 p7 and S3 p7 list bar values without a year for each bar; once FY2022 = 37.3 and FY2023 = 40.8 are taken out, S1 leaves 23, 25 or 17, S2 leaves 23 or 25 and S3 leaves 23 for FY2021, so a reviewer reads the chart images; the S1 FY2019 fact (23.0) depends on the same reading. | O49: https://vanillabonds.com/dossier-data/pdf/katjes/katjes-2023-annual-report.pdf#page=7
A50: F049 | B50: financials | C50: ebitda | D50: EBITDA (as reported) | E50: FY2022 | F50: 37.3 | G50: EUR m | H50: EBITDA as labelled in the management report | I50: S1 | J50: 32 | K50: amortisation) amounted to EUR 40.8 million in the financial year 2023 (2022: EUR 37.3 million) | L50: ok | M50: demo reviewer | O50: https://vanillabonds.com/dossier-data/pdf/katjes/katjes-2023-annual-report.pdf#page=32
A51: F050 | B51: financials | C51: ebitda | D51: EBITDA (as reported) | E51: FY2023 | F51: 40.8 | G51: EUR m | H51: EBITDA as labelled in the management report; EBITDA margin 10.8% (2022: 12.7%) | I51: S1 | J51: 32 | K51: amortisation) amounted to EUR 40.8 million in the financial year 2023 (2022: EUR 37.3 million) | L51: pend | N51: conflict: S1·p32 40.8 vs S2·p29 40.8 vs S3·p7 23.0; primary per fact agent: S2 p29 - S2 is the later audited report carrying FY2023 and its comparative equals S1 p32; S3 carries no FY2023 statement, and its 23.0 is a chart bar from p7 assigned to FY2023. | O51: https://vanillabonds.com/dossier-data/pdf/katjes/katjes-2023-annual-report.pdf#page=32
A52: F051 | B52: financials | C52: ebitda | D52: EBITDA (as reported) | E52: FY2024E | G52: EUR m | H52: Management guidance for 2024: EBITDA margin between 9% and 10% (no absolute figure) | I52: S1 | J52: 41 | K52: earnings, Katjes International is aiming for an EBITDA margin of between 9% and 10% in the financial year 2024. | L52: ok | M52: demo reviewer | O52: https://vanillabonds.com/dossier-data/pdf/katjes/katjes-2023-annual-report.pdf#page=41
...

Sheet Documents
A1: Source | B1: Kind | C1: Period | D1: Date | E1: Origin | F1: Audited | G1: Pages | H1: Link
A2: S1 | B2: annual report | C2: FY2023 | D2: 2024-03-27 | E2: Katjes International GmbH & Co. KG, Emmerich am Rhein (consolidated financial statements and group management report; auditor EY GmbH & Co. KG) | F2: TRUE | G2: 95 | H2: https://vanillabonds.com/dossier-data/pdf/katjes/katjes-2023-annual-report.pdf
A3: S2 | B3: annual report | C3: FY2024 | D3: 2025-04-09 | E3: Katjes International GmbH & Co. KG (audited by EY GmbH & Co. KG) | F3: TRUE | G3: 91 | H3: https://vanillabonds.com/dossier-data/pdf/katjes/katjes-2024-annual-report.pdf
A4: S3 | B4: annual report | C4: FY2025 | D4: 2026-04-02 | E4: Katjes International GmbH & Co. KG, Emmerich am Rhein (management; auditor EY GmbH & Co. KG) | F4: TRUE | G4: 92 | H4: https://vanillabonds.com/dossier-data/pdf/katjes/katjes-2025-annual-report.pdf
A5: S4 | B5: term sheet | C5: 2023-09-21 to 2028-09-21 (bond 2023/2028) | D5: 2023-09-21 | E5: Katjes International GmbH & Co. KG (issuer; author of the sheet not stated) | F5: FALSE | G5: 2 | H5: https://vanillabonds.com/dossier-data/pdf/katjes/katjes-bond-2023-2028-terms.pdf
A6: S5 | B6: interim report | C6: H1-2026 | D6: 2026-09-08 | E6: Katjes International GmbH & Co. KG | F6: FALSE | G6: 52 | H6: https://vanillabonds.com/dossier-data/pdf/katjes/katjes-h1-2026-interim-report.pdf
A7: S6 | B7: web page | D7: 2026-10-20 | E7: GLEIF | F7: FALSE | G7: 0 | H7: https://api.gleif.org/api/v1/lei-records?filter[entity.legalName]=Katjes International
A8: S7 | B8: web page | D8: 2026-10-20 | E8: onvista | F8: FALSE | G8: 0 | H8: https://www.onvista.de/anleihen/KATJES-INT-IHS-23-28-Anleihe-NO0012888769
A9: S8 | B9: web page | D9: 2026-10-20 | E9: EQS-News via Placera | F9: FALSE | G9: 0 | H9: https://www.placera.se/pressmeddelanden/katjes-international-successfully-taps-its-corporate-bond-by-eur-70-million-20250805
A10: S9 | B10: web page | D10: 2026-10-20 | E10: Hogan Lovells | F10: FALSE | G10: 0 | H10: https://www.hlc.com/de/news/hogan-lovells-beraet-katjes-bei-aufstockung-ihrer-nordic-bonds
A11: S10 | B11: web page | D11: 2026-10-20 | E11: yumda (article dated 2026-04-09, reproducing the company release) | F11: FALSE | G11: 0 | H11: https://www.yumda.com/de/news/1188448/katjes-mit-rekord-bei-umsatz-und-ergebnis.html
A12: S11 | B12: web page | D12: 2026-10-20 | E12: yumda | F12: FALSE | G12: 0 | H12: https://www.yumda.com/de/news/1147058/katjes-und-zuckerproduzenten-streiten-vor-gericht-um-schadensersatz.html
A13: S12 | B13: web page | D13: 2026-10-20 | E13: Wikipedia | F13: FALSE | G13: 0 | H13: https://en.wikipedia.org/wiki/Katjes_International
